<mujoco model="aubo_i5">
    <compiler angle="radian"/>
    <size njmax="500" nconmax="100"/>
    <default>
        <joint armature="0.2" damping="0.2" />  <!--damping="0.1"-->
        <default class="visual">
            <geom group="2" type="mesh" contype="0" conaffinity="0" density="0"/>
        </default>
        <default class="collision">
            <geom group="3" type="mesh" rgba="1 1 1 1" density="2700"/>
        </default>
    </default>

<option timestep="0.005" gravity="0 0 -9.81" integrator="implicitfast" impratio="10">
    <flag contact="enable" energy="enable" gravity="enable"/>
</option>

<visual>
    <headlight diffuse="0.6 0.6 0.6" ambient="0.1 0.1 0.1" specular="0 0 0"/>
    <rgba haze="0.15 0.25 0.35 1"/>
    <global azimuth="120" elevation="-20"/>
</visual>

<asset>
    <material name="Opaque(63,63,63)" specular="0.5" shininess="0.5" rgba="0.250980 0.250980 0.250980 1.0"/>
    <material name="Opaque(232,133,0)" specular="0.5" shininess="0.5" rgba="0.909804 0.521569 0.000000 1.0"/>

    <mesh name="link0_0" file="../Aubo_i5/meshes/visual/link0/link0_0.obj"/>
    <mesh name="link1_0" file="../Aubo_i5/meshes/visual/link1/link1_0.obj"/>
    <mesh name="link1_1" file="../Aubo_i5/meshes/visual/link1/link1_1.obj"/>
    <mesh name="link1_2" file="../Aubo_i5/meshes/visual/link1/link1_2.obj"/>
    <mesh name="link2_0" file="../Aubo_i5/meshes/visual/link2/link2_0.obj"/>
    <mesh name="link2_1" file="../Aubo_i5/meshes/visual/link2/link2_1.obj"/>
    <mesh name="link2_2" file="../Aubo_i5/meshes/visual/link2/link2_2.obj"/>
    <mesh name="link3_0" file="../Aubo_i5/meshes/visual/link3/link3_0.obj"/>
    <mesh name="link3_1" file="../Aubo_i5/meshes/visual/link3/link3_1.obj"/>
    <mesh name="link4_0" file="../Aubo_i5/meshes/visual/link4/link4_0.obj"/>
    <mesh name="link4_1" file="../Aubo_i5/meshes/visual/link4/link4_1.obj"/>
    <mesh name="link5_0" file="../Aubo_i5/meshes/visual/link5/link5_0.obj"/>
    <mesh name="link5_1" file="../Aubo_i5/meshes/visual/link5/link5_1.obj"/>
    <mesh name="link6_0" file="../Aubo_i5/meshes/visual/link6/link6_0.obj"/>

    <mesh name="link0" file="../Aubo_i5/meshes/collision/link0.STL"/>
    <mesh name="link1" file="../Aubo_i5/meshes/collision/link1.STL"/>
    <mesh name="link2" file="../Aubo_i5/meshes/collision/link2.STL"/>
    <mesh name="link3" file="../Aubo_i5/meshes/collision/link3.STL"/>
    <mesh name="link4" file="../Aubo_i5/meshes/collision/link4.STL"/>
    <mesh name="link5" file="../Aubo_i5/meshes/collision/link5.STL"/>
    <mesh name="link6" file="../Aubo_i5/meshes/collision/link6.STL"/>
</asset>

<worldbody>
    <body name="base_link" pos="0.8 0.6 0.745">
        <inertial pos="5.28033e-09 0.00159669 0.0165705" quat="0.495398 0.50456 -0.50456 0.495398" mass="1.43822" diaginertia="0.0055319 0.003103 0.0028571"/>
        <geom mesh="link0_0" pos="0 0 0" quat="180 180 0 1" material="Opaque(63,63,63)" class="visual"/>
        <geom type="mesh" rgba="1 1 1 1" mesh="link0" class="collision"/>

        <body name="shoulder_Link" pos="0 0 0.122" quat="0 0 0 1">
            <inertial pos="-1e-05 0.001807 -0.013854" quat="0.999902 -0.0139146 -0.000554021 -0.0014145" mass="4.84858" diaginertia="0.011842 0.0118029 0.00810013"/>
            <joint name="shoulder_joint" pos="0 0 0" axis="0 0 1" limited="true" range="-6.28319 6.28319" damping="8.0" frictionloss="10.0"/>
            <geom mesh="link1_0" pos="0 0 0" quat="180 180 0 1" material="Opaque(232,133,0)" class="visual"/>
            <geom mesh="link1_1" pos="0 0 0" quat="180 180 0 1" material="Opaque(63,63,63)" class="visual"/>
            <geom type="mesh" rgba="1 1 1 1" mesh="link1" class="collision"/>

            <body name="upperArm_Link" pos="0 0.1215 0" quat="0.5 -0.5 -0.5 -0.5">
                <inertial pos="0.204 0 0.006603" quat="0.500012 0.500012 0.499988 0.499988" mass="10.8363" diaginertia="0.432805 0.425155 0.026024"/>
                <joint name="upperArm_joint" pos="0 0 0" axis="0 0 1" limited="true" range="-6.28319 6.28319" damping="8.0" frictionloss="10.0"/>
                <geom mesh="link2_0" pos="0 0 0" quat="180 180 0 1" material="Opaque(232,133,0)" class="visual"/>
                <geom mesh="link2_1" pos="0 0 0" quat="180 180 0 1" material="Opaque(63,63,63)" class="visual"/>
                <geom mesh="link2_2" pos="0 0 0" quat="180 180 0 1" material="Opaque(63,63,63)" class="visual"/>
                <geom type="mesh" rgba="1 1 1 1" mesh="link2" class="collision"/>

                <body name="foreArm_Link" pos="0.408 0 0" quat="0 -1 0 0">
                    <inertial pos="0.264626 -2e-05 0.093611" quat="0.498564 0.501492 0.499882 0.500057" mass="2.84917" diaginertia="0.065327 0.0646765 0.00363354"/>
                    <joint name="foreArm_joint" pos="0 0 0" axis="0 0 1" limited="true" range="-6.28319 6.28319" damping="8.0" frictionloss="10.0"/>
                    <geom mesh="link3_0" pos="0 0 0" quat="180 180 0 1" material="Opaque(63,63,63)" class="visual"/>
                    <geom mesh="link3_1" pos="0 0 0" quat="180 180 0 1" material="Opaque(232,133,0)" class="visual"/>
                    <geom type="mesh" rgba="1 1 1 1" mesh="link3" class="collision"/>

                    <body name="wrist1_Link" pos="0.376 0 0" quat="0 0.707107 0.707107 0">
                        <inertial pos="3.8e-05 0.011278 -0.001539" quat="0.68759 0.725716 -0.0157544 0.0175555" mass="1.62802" diaginertia="0.00195105 0.00193322 0.00115172"/>
                        <joint name="wrist1_joint" pos="0 0 0" axis="0 0 1" limited="true" range="-6.28319 6.28319" damping="2.5" frictionloss="3.0"/>
                        <geom mesh="link4_0" pos="0 0 0" quat="180 180 0 1" material="Opaque(63,63,63)" class="visual"/>
                        <geom mesh="link4_1" pos="0 0 0" quat="180 180 0 1" material="Opaque(232,133,0)" class="visual"/>
                        <geom type="mesh" rgba="1 1 1 1" mesh="link4" class="collision"/>

                        <body name="wrist2_Link" pos="0 0.1025 0" quat="0.707107 -0.707107 0 0">
                            <inertial pos="-3.8e-05 -0.011278 -0.001539" quat="0.725716 0.68759 0.0175555 -0.0157544" mass="1.62802" diaginertia="0.00195105 0.00193322 0.00115172"/>
                            <joint name="wrist2_joint" pos="0 0 0" axis="0 0 1" limited="true" range="-6.28319 6.28319" damping="2.5" frictionloss="3.0"/>
                            <geom mesh="link5_0" pos="0 0 0" quat="180 180 0 1" material="Opaque(63,63,63)" class="visual"/>
                            <geom mesh="link5_1" pos="0 0 0" quat="180 180 0 1" material="Opaque(232,133,0)" class="visual"/>
                            <geom type="mesh" rgba="1 1 1 1" mesh="link5" class="collision"/>

                            <body name="wrist3_Link" pos="0 -0.094 0" quat="0.707107 0.707107 0 0">
                                <inertial pos="2.2e-05 0.0006 -0.017081" quat="0.503459 0.496517 -0.496517 0.503459" mass="0.1978" diaginertia="0.000184014 0.000118 0.000111986"/>
                                <joint name="wrist3_joint" pos="0 0 0" axis="0 0 1" limited="true" range="-6.28319 6.28319" damping="2.5" frictionloss="3.0"/>
                                <geom mesh="link6_0" pos="0 0 0" quat="180 180 0 1" material="Opaque(63,63,63)" class="visual"/>
                                <geom type="mesh" pos="0 0 0" mesh="link6" class="collision"/>

                                <body name="flange" pos="0 0 0" quat="1 0 0 0">
                                    <site name="tcp" pos="0 0 0" size="0.01" rgba="0 1 0 1"/>
                                    <site name="end_force_sensor_site" type="cylinder" size="0.036 0.001" pos="0 0 0.001" rgba="1 1 0 0.3"/>
                                    <body name="arm_camera" pos="0 -0.02 0" quat="1 0 0 0">
                                        <camera name="flange_cam" mode="fixed" pos="0 0 0" xyaxes="1 0 0 0 -1 0"/>
                                        <geom type="box" size="0.01 0.01 0.01" rgba="1 0 0 0.5" contype="0" conaffinity="0"/>
                                    </body>
                                </body>
                            </body>
                        </body>
                    </body>
                </body>
            </body>
        </body>
    </body>
</worldbody>

<actuator>
    <position ctrllimited="true" ctrlrange="-6.28 6.28" joint="shoulder_joint" name="q1" kp="30500" kv="20" gear="1"/>
    <position ctrllimited="true" ctrlrange="-6.28 6.28" joint="upperArm_joint" name="q2" kp="8500" kv="190" gear="1"/>
    <position ctrllimited="true" ctrlrange="-6.28 6.28" joint="foreArm_joint" name="q3" kp="6500" kv="99" gear="1"/>
    <position ctrllimited="true" ctrlrange="-6.28 6.28" joint="wrist1_joint" name="q4" kp="700" kv="7.3" gear="1"/>
    <position ctrllimited="true" ctrlrange="-6.28 6.28" joint="wrist2_joint" name="q5" kp="150" kv="5.0" gear="1"/>
    <position ctrllimited="true" ctrlrange="-6.28 6.28" joint="wrist3_joint" name="q6" kp="150" kv="5.0" gear="1"/>
</actuator>

<sensor>
    <force name="end_force_sensor" site="end_force_sensor_site" cutoff="50"/>
    <torque name="end_torque_sensor" site="end_force_sensor_site" cutoff="10"/>
</sensor>
</mujoco>
