<?xml version="1.0" encoding="UTF-8"?>
<mujoco model="rm_65_description">
  <!-- 配置编译器和选项 -->
  <compiler angle="radian"/>
  <option gravity="0 0 0" timestep="0.0001" integrator="RK4"/>
  
  <!-- 默认设置 -->
  <default>
    <geom friction="0 0 0" contype="1" conaffinity="1"/>
    <joint damping="1.0"/>
  </default>

  <!-- 资源定义 -->
  <asset>
    <mesh name="base" file="base.STL"/>
    <mesh name="base_link" file="base_link.STL"/>
    <mesh name="link1" file="link1.STL"/>
    <mesh name="link2" file="link2.STL"/>
    <mesh name="link3" file="link3.STL"/>
    <mesh name="link4" file="link4.STL"/>
    <mesh name="link5" file="link5.STL"/>
    <mesh name="link6" file="link6.STL"/>
    <mesh name="l1" file="l1.STL"/>
    <mesh name="l2" file="l2.STL"/>
  </asset>

  <!-- 执行器定义 -->
  <actuator>
    <!-- 第一个机械臂的关节控制器 -->
    <position name="act_joint1" joint="joint1" kp="10" kv="0.5" ctrlrange="-300 300"/>
    <position name="act_joint2" joint="joint2" kp="10" kv="0.5" ctrlrange="-300 300"/>
    <position name="act_joint3" joint="joint3" kp="10" kv="0.5" ctrlrange="-300 300"/>
    <position name="act_joint4" joint="joint4" kp="10" kv="0.5" ctrlrange="-300 300"/>
    <position name="act_joint5" joint="joint5" kp="10" kv="0.5" ctrlrange="-300 300"/>
    <position name="act_joint6" joint="joint6" kp="10" kv="0.5" ctrlrange="-300 300"/>
    
    <!-- 第二个机械臂的关节控制器 -->
    <position name="act_joint1_1" joint="joint1_1" kp="10" kv="0.5" ctrlrange="-300 300"/>
    <position name="act_joint2_1" joint="joint2_1" kp="10" kv="0.5" ctrlrange="-300 300"/>
    <position name="act_joint3_1" joint="joint3_1" kp="10" kv="0.5" ctrlrange="-300 300"/>
    <position name="act_joint4_1" joint="joint4_1" kp="10" kv="0.5" ctrlrange="-300 300"/>
    <position name="act_joint5_1" joint="joint5_1" kp="10" kv="0.5" ctrlrange="-300 300"/>
    <position name="act_joint6_1" joint="joint6_1" kp="10" kv="0.5" ctrlrange="-300 300"/>
  </actuator>

  <!-- 世界体 -->
  <worldbody>
    <!-- 基座和其他固定部件 -->
    <geom pos="-0.94 0.0707485 0.045" quat="0.018246 0.0182315 0.70659 0.707153" type="mesh" rgba="1 1 1 1" mesh="base"/>
    <geom pos="0.104944 -8.35921e-05 0" quat="0.707107 0.000281544 0.707107 0.000281544" type="mesh" rgba="1 1 1 1" mesh="base_link"/>
    <geom pos="-0.0950557 7.56732e-05 0" quat="0.000844632 -0.707107 0.000281544 0.707107" type="mesh" rgba="1 1 1 1" mesh="base_link"/>
    
    <!-- 第一个机械臂 -->
    <body name="Link1" pos="0.345444 -8.35922e-05 1.5251e-07" quat="0.707107 0.000281544 0.707107 0.000281544">
      <inertial pos="1.22263e-08 0.021108 -0.0251854" quat="0.988851 -0.148906 -2.80074e-05 -0.000243475" mass="0.593563" diaginertia="0.00126614 0.00124677 0.000496264"/>
      <joint name="joint1" pos="0 0 0" axis="0 0 1" range="-3.1 3.1" actuatorfrcrange="-60 60"/>
      <geom type="mesh" rgba="1 1 1 1" mesh="link1"/>
      
      <body name="Link2" quat="0.499998 0.5 -0.5 0.500002">
        <inertial pos="0.152256 4.75384e-07 -0.0062026" quat="1.2834e-05 0.785787 1.90512e-05 0.618497" mass="0.864175" diaginertia="0.00735632 0.00733754 0.000513875"/>
        <joint name="joint2" pos="0 0 0" axis="0 0 1" range="-2.268 2.268" actuatorfrcrange="-60 60"/>
        <geom type="mesh" rgba="1 1 1 1" mesh="link2"/>
        
        <body name="Link3" pos="0.256 0 0" quat="0.707105 0 0 0.707108">
          <inertial pos="5.05313e-06 -0.0595926 0.0105691" quat="0.424678 0.56496 -0.565554 0.424992" mass="0.289634" diaginertia="0.00065604 0.000637371 0.000114622"/>
          <joint name="joint3" pos="0 0 0" axis="0 0 1" range="-2.355 2.355" actuatorfrcrange="-30 30"/>
          <geom type="mesh" rgba="1 1 1 1" mesh="link3"/>
          
          <body name="Link4" pos="0 -0.21 0" quat="0.707105 0.707108 0 0">
            <inertial pos="1.15517e-06 -0.0180424 -0.0215395" quat="0.990405 0.138195 -7.01319e-06 0.000110532" mass="0.23942" diaginertia="0.000285939 0.000275318 0.000107298"/>
            <joint name="joint4" pos="0 0 0" axis="0 0 1" range="-3.1 3.1" actuatorfrcrange="-10 10"/>
            <geom type="mesh" rgba="1 1 1 1" mesh="link4"/>
            
            <body name="Link5" quat="0.707105 -0.707108 0 0">
              <inertial pos="3.19795e-06 -0.0593808 0.00736804" quat="0.419765 0.568659 -0.5692 0.420041" mass="0.2188" diaginertia="0.000358615 0.00035054 8.07958e-05"/>
              <joint name="joint5" pos="0 0 0" axis="0 0 1" range="-2.233 2.233" actuatorfrcrange="-10 10"/>
              <geom type="mesh" rgba="1 1 1 1" mesh="link5"/>
              
              <body name="Link6" pos="0 -0.144 0" quat="0.707105 0.707108 0 0">
                <site name="right_tool" type="sphere" pos="0.01 -0.01 0.2" size="0.01" rgba="1 0 0 1"/>
                <inertial pos="0.000191075 -0.000106132 -0.00339016" quat="0.543247 0.439153 0.452315 0.554471" mass="0.242602" diaginertia="0.000201928 0.000162265 0.000150834"/>
                <joint name="joint6" pos="0 0 0" axis="0 0 1" range="-6.28 6.28" actuatorfrcrange="-10 10"/>
                <geom type="mesh" rgba="1 1 1 1" mesh="link6"/>
                <geom pos="0 0 0" quat="0.000563312 -0.706825 0.000562864 0.707388" type="mesh" rgba="1 1 1 1" mesh="l2"/>
                <!-- 新增胶囊体，用于右臂碰撞检测，fromto 定义本体局部坐标中两个端点 -->
                <geom name="capsule_right" type="capsule" fromto="0 0 0 0 0 0.15" size="0.03" rgba="1 0 0 0.3" contype="1" conaffinity="1"/>
              </body>
            </body>
          </body>
        </body>
      </body>
    </body>
    
    <!-- 第二个机械臂 -->
    <body name="Link1_1" pos="-0.335555 0.000458706 1.5251e-07" quat="0.000844632 -0.707107 0.000281544 0.707107">
      <inertial pos="1.22263e-08 0.021108 -0.0251854" quat="0.988851 -0.148906 -2.80074e-05 -0.000243475" mass="0.593563" diaginertia="0.00126614 0.00124677 0.000496264"/>
      <joint name="joint1_1" pos="0 0 0" axis="0 0 1" range="-3.1 3.1" actuatorfrcrange="-60 60"/>
      <geom type="mesh" rgba="1 1 1 1" mesh="link1"/>
      
      <body name="Link2_1" quat="0.499998 0.5 -0.5 0.500002">
        <inertial pos="0.152256 4.75384e-07 -0.0062026" quat="1.2834e-05 0.785787 1.90512e-05 0.618497" mass="0.864175" diaginertia="0.00735632 0.00733754 0.000513875"/>
        <joint name="joint2_1" pos="0 0 0" axis="0 0 1" range="-2.268 2.268" actuatorfrcrange="-60 60"/>
        <geom type="mesh" rgba="1 1 1 1" mesh="link2"/>
        
        <body name="Link3_1" pos="0.256 0 0" quat="0.707105 0 0 0.707108">
          <inertial pos="5.05313e-06 -0.0595926 0.0105691" quat="0.424678 0.56496 -0.565554 0.424992" mass="0.289634" diaginertia="0.00065604 0.000637371 0.000114622"/>
          <joint name="joint3_1" pos="0 0 0" axis="0 0 1" range="-2.355 2.355" actuatorfrcrange="-30 30"/>
          <geom type="mesh" rgba="1 1 1 1" mesh="link3"/>
          
          <body name="Link4_1" pos="0 -0.21 0" quat="0.707105 0.707108 0 0">
            <inertial pos="1.15517e-06 -0.0180424 -0.0215395" quat="0.990405 0.138195 -7.01319e-06 0.000110532" mass="0.23942" diaginertia="0.000285939 0.000275318 0.000107298"/>
            <joint name="joint4_1" pos="0 0 0" axis="0 0 1" range="-3.1 3.1" actuatorfrcrange="-10 10"/>
            <geom type="mesh" rgba="1 1 1 1" mesh="link4"/>
            
            <body name="Link5_1" quat="0.707105 -0.707108 0 0">
              <inertial pos="3.19795e-06 -0.0593808 0.00736804" quat="0.419765 0.568659 -0.5692 0.420041" mass="0.2188" diaginertia="0.000358615 0.00035054 8.07958e-05"/>
              <joint name="joint5_1" pos="0 0 0" axis="0 0 1" range="-2.233 2.233" actuatorfrcrange="-10 10"/>
              <geom type="mesh" rgba="1 1 1 1" mesh="link5"/>
              
              <body name="Link6_1" pos="0 -0.144 0" quat="0.707105 0.707108 0 0">
                <site name="left_tool" type="sphere" pos="-0.008 0.075 0.15" size="0.01" rgba="1 0 0 1"/>
                <inertial pos="0.000191075 -0.000106132 -0.00339016" quat="0.425342 0.553051 0.571333 0.432201" mass="0.242602" diaginertia="0.000201934 0.000162624 0.000150468"/>
                <joint name="joint6_1" pos="0 0 0" axis="0 0 1" range="-6.28 6.28" actuatorfrcrange="-10 10"/>
                <geom type="mesh" rgba="1 1 1 1" mesh="link6"/>
                <geom pos="0 0 0" quat="0.707388 0 -0.706825 0" type="mesh" rgba="1 1 1 1" mesh="l1"/>
                <!-- 新增胶囊体，用于左臂碰撞检测 -->
                <geom name="capsule_left" type="capsule" fromto="0 0 0 0 0 0.15" size="0.03" rgba="0 0 1 0.3" contype="1" conaffinity="1"/>
              </body>
            </body>
          </body>
        </body>
      </body>
    </body>

    <!-- 目标位置的视觉标记 -->
    <body name="target_right" pos="-0.1 -0.6 0.05">
        <geom type="sphere" size="0.02" rgba="1 0 0 0.5"/>
    </body>
    <body name="target_left" pos="-0.1 -0.6 0">
        <geom type="sphere" size="0.02" rgba="0 1 0 0.5"/>
    </body>
  </worldbody>
</mujoco>
