<mujoco model="so_arm100">
  <compiler angle="radian" meshdir="assets/"/>

  <option cone="elliptic" impratio="10"/>

  <asset>
    <material name="orange" rgba="1.0 0.331 0.0 1.0" specular="0.1" shininess="0.1"/>
    <material name="black" rgba="0.1 0.1 0.1 1.0" specular="0.1" shininess="0.1"/>
    <material name="white" rgba="1 1 1 1"/>
    <material name="off_white" rgba="0.901961 0.921569 0.929412 1"/>

    <mesh name="Base" file="Base.stl"/>
    <mesh name="Base_Motor" file="Base_Motor.stl"/>
    <mesh name="Rotation_Pitch" file="Rotation_Pitch.stl"/>
    <mesh name="Rotation_Pitch_Motor" file="Rotation_Pitch_Motor.stl"/>
    <mesh name="Upper_Arm" file="Upper_Arm.stl"/>
    <mesh name="Upper_Arm_Motor" file="Upper_Arm_Motor.stl"/>
    <mesh name="Lower_Arm" file="Lower_Arm.stl"/>
    <mesh name="Lower_Arm_Motor" file="Lower_Arm_Motor.stl"/>
    <mesh name="Wrist_Pitch_Roll" file="Wrist_Pitch_Roll.stl"/>
    <mesh name="Wrist_Pitch_Roll_Motor" file="Wrist_Pitch_Roll_Motor.stl"/>
    <mesh name="Fixed_Jaw" file="Fixed_Jaw.stl"/>
    <mesh name="Fixed_Jaw_Motor" file="Fixed_Jaw_Motor.stl"/>
    <mesh name="Fixed_Jaw_Collision_1" file="Fixed_Jaw_Collision_1.stl"/>
    <mesh name="Fixed_Jaw_Collision_2" file="Fixed_Jaw_Collision_2.stl"/>

    <mesh name="hand_c" file="hand.stl"/>

    <mesh file="hand_0.obj"/>
    <mesh file="hand_1.obj"/>
    <mesh file="hand_2.obj"/>
    <mesh file="hand_3.obj"/>
    <mesh file="hand_4.obj"/>
    <mesh file="finger_0.obj"/>
    <mesh file="finger_1.obj"/>
  </asset>

  <default>
    <default class="so_arm100">
      <!-- 添加finger -->
      <default class="finger">
        <joint axis="0 1 0" type="slide" range="0 0.04"/>
      </default>
      <joint frictionloss="0.1" armature="0.1"/>
      <position kp="50" dampratio="1" forcerange="-35 35" ctrlrange="-3.14158 3.14158"/>
      <default class="Rotation">
        <joint axis="0 1 0" range="-2.2 2.2"/>
      </default>
      <default class="Pitch">
        <joint axis="1 0 0" range="-3.14158 0.2"/>
      </default>
      <default class="Elbow">
        <joint axis="1 0 0" range="0 3.14158"/>
      </default>
      <default class="Wrist_Pitch">
        <joint axis="1 0 0" range="-2.0 1.8"/>
      </default>
      <default class="Wrist_Roll">
        <joint axis="0 1 0" range="-3.14158 3.14158"/>
      </default>
      <default class="Jaw">
        <!-- 改旋转轴 -->
        <joint axis="0 1 0" range="-0.2 2.0"/>
      </default>
      <default class="visual">
        <geom type="mesh" contype="0" conaffinity="0" density="0" group="2" material="orange"/>
        <default class="motor_visual">
          <geom material="black"/>
        </default>
      </default>
      <default class="collision">
        <geom type="mesh" group="3"/>
        <default class="fingertip_pad_collision_1">
          <geom type="box" size="0.0085 0.004 0.0085" pos="0 0.0055 0.0445"/>
        </default>
        <default class="fingertip_pad_collision_2">
          <geom type="box" size="0.003 0.002 0.003" pos="0.0055 0.002 0.05"/>
        </default>
        <default class="fingertip_pad_collision_3">
          <geom type="box" size="0.003 0.002 0.003" pos="-0.0055 0.002 0.05"/>
        </default>
        <default class="fingertip_pad_collision_4">
          <geom type="box" size="0.003 0.002 0.0035" pos="0.0055 0.002 0.0395"/>
        </default>
        <default class="fingertip_pad_collision_5">
          <geom type="box" size="0.003 0.002 0.0035" pos="-0.0055 0.002 0.0395"/>
        </default>
      </default>
    </default>
  </default>

  <worldbody>
    <body name="Base" childclass="so_arm100">
      <geom type="mesh" mesh="Base" class="visual"/>
      <geom type="mesh" mesh="Base_Motor" class="motor_visual"/>
      <geom type="mesh" mesh="Base" class="collision"/>
      <body name="Rotation_Pitch" pos="0 -0.0452 0.0165" quat="0.707105 0.707108 0 0">
        <inertial pos="-9.07886e-05 0.0590972 0.031089" quat="0.363978 0.441169 -0.623108 0.533504" mass="0.119226"
          diaginertia="5.94278e-05 5.89975e-05 3.13712e-05"/>
        <joint name="Rotation" class="Rotation"/>
        <geom type="mesh" mesh="Rotation_Pitch" class="visual"/>
        <geom type="mesh" mesh="Rotation_Pitch_Motor" class="motor_visual"/>
        <geom type="mesh" mesh="Rotation_Pitch" class="collision"/>
        <body name="Upper_Arm" pos="0 0.1025 0.0306" euler="1.57079 0 0">
          <inertial pos="-1.72052e-05 0.0701802 0.00310545" quat="0.50104 0.498994 -0.493562 0.50632" mass="0.162409"
            diaginertia="0.000213312 0.000167164 7.01522e-05"/>
          <joint name="Pitch" class="Pitch"/>
          <geom type="mesh" mesh="Upper_Arm" class="visual"/>
          <geom type="mesh" mesh="Upper_Arm_Motor" class="motor_visual"/>
          <geom type="mesh" mesh="Upper_Arm" class="collision"/>
          <body name="Lower_Arm" pos="0 0.11257 0.028" euler="-1.57079 0 0">
            <inertial pos="-0.00339604 0.00137796 0.0768007" quat="0.701995 0.0787996 0.0645626 0.704859"
              mass="0.147968" diaginertia="0.000138803 0.000107748 4.84242e-05"/>
            <joint name="Elbow" class="Elbow"/>
            <geom type="mesh" mesh="Lower_Arm" class="visual"/>
            <geom type="mesh" mesh="Lower_Arm_Motor" class="motor_visual"/>
            <geom type="mesh" mesh="Lower_Arm" class="collision"/>
            <body name="Wrist_Pitch_Roll" pos="0 0.0052 0.1349" euler="-1.57079 0 0">
              <inertial pos="-0.00852653 -0.0352279 -2.34622e-05" quat="-0.0522806 0.705235 0.0549524 0.704905"
                mass="0.0661321" diaginertia="3.45403e-05 2.39041e-05 1.94704e-05"/>
              <joint name="Wrist_Pitch" class="Wrist_Pitch"/>
              <geom type="mesh" mesh="Wrist_Pitch_Roll" class="visual"/>
              <geom type="mesh" mesh="Wrist_Pitch_Roll_Motor" class="motor_visual"/>
              <geom type="mesh" mesh="Wrist_Pitch_Roll" class="collision"/>
              <body name="Fixed_Jaw" pos="0 -0.0601 0" euler="0 1.57079 0">
                <inertial pos="0.00552377 -0.0280167 0.000483583" quat="0.41836 0.620891 -0.350644 0.562599"
                  mass="0.0929859" diaginertia="5.03136e-05 4.64098e-05 2.72961e-05"/>
                <joint name="Wrist_Roll" class="Wrist_Roll"/>
                <geom type="mesh" mesh="Fixed_Jaw" class="visual"/>
                <geom type="mesh" mesh="Fixed_Jaw_Motor" class="motor_visual"/>
                <geom type="mesh" mesh="Fixed_Jaw_Collision_1" class="collision"/>
                <geom type="mesh" mesh="Fixed_Jaw_Collision_2" class="collision"/>
                <!-- 比原来的Move Jaw 绕x轴旋转90° -->
                <!-- <body name="hand" pos="-0.0202 -0.0244 0" quat="0.9238795 0 0 -0.3826834"> -->
                <body name="hand" pos="-0.0202 -0.0244 0" quat="2.5973612402897724e-06 -2.597342159154704e-06 0.7071041838348479 -0.7071093785382472">
                      <inertial mass="0.73" pos="-0.01 0 0.03" diaginertia="0.001 0.0025 0.0017"/>
                      <joint name="Jaw" class="Jaw"/>
                      <geom mesh="hand_0" material="off_white" class="visual"/>
                      <geom mesh="hand_1" material="black" class="visual"/>
                      <geom mesh="hand_2" material="black" class="visual"/>
                      <geom mesh="hand_3" material="white" class="visual"/>
                      <geom mesh="hand_4" material="off_white" class="visual"/>
                      <geom mesh="hand_c" class="collision"/>
                      <body name="left_finger" pos="0 0 0.0584">
                        <inertial mass="0.005" pos="0 0 0" diaginertia="2.375e-6 2.375e-6 7.5e-7"/>
                        <joint name="finger_joint1" class="finger"/>
                        <geom mesh="finger_0" material="off_white" class="visual"/>
                        <geom mesh="finger_1" material="black" class="visual"/>
                        <geom mesh="finger_0" class="collision"/>
                        <geom class="fingertip_pad_collision_1"/>
                        <geom class="fingertip_pad_collision_2"/>
                        <geom class="fingertip_pad_collision_3"/>
                        <geom class="fingertip_pad_collision_4"/>
                        <geom class="fingertip_pad_collision_5"/>
                      </body>
                      <body name="right_finger" pos="0 0 0.0584" quat="0 0 0 1">
                        <inertial mass="0.005" pos="0 0 0" diaginertia="2.375e-6 2.375e-6 7.5e-7"/>
                        <joint name="finger_joint2" class="finger"/>
                        <geom mesh="finger_0" material="off_white" class="visual"/>
                        <geom mesh="finger_1" material="black" class="visual"/>
                        <geom mesh="finger_0" class="collision"/>
                        <geom class="fingertip_pad_collision_1"/>
                        <geom class="fingertip_pad_collision_2"/>
                        <geom class="fingertip_pad_collision_3"/>
                        <geom class="fingertip_pad_collision_4"/>
                        <geom class="fingertip_pad_collision_5"/>
                      </body>
                    </body>
              </body>
            </body>
          </body>
        </body>
      </body>
    </body>
  </worldbody>
  <!-- 肌腱，用于描述两个关节的同步 -->
  <tendon>
    <fixed name="split">
      <!-- 两个关节各获得一半的驱动力 -->
      <joint joint="finger_joint1" coef="0.5"/>
      <joint joint="finger_joint2" coef="0.5"/>
    </fixed>
  </tendon>

  <equality>
    <joint joint1="finger_joint1" joint2="finger_joint2" solimp="0.95 0.99 0.001" solref="0.005 1"/>
  </equality>

  <actuator>
    <position class="Rotation" name="Rotation" joint="Rotation"/>
    <position class="Pitch" name="Pitch" joint="Pitch"/>
    <position class="Elbow" name="Elbow" joint="Elbow"/>
    <position class="Wrist_Pitch" name="Wrist_Pitch" joint="Wrist_Pitch"/>
    <position class="Wrist_Roll" name="Wrist_Roll" joint="Wrist_Roll"/>
    <position class="Jaw" name="Jaw" joint="Jaw"/>
    <!-- 添加一个执行器，指定跟腱为split -->
    <general name="actuator8" tendon="split" forcerange="-35 35" ctrlrange="-30 30"
      gainprm="0.01568627451 0 0" biasprm="0 -100 -10"/>
  </actuator>

  <contact>
    <exclude body1="Base" body2="Rotation_Pitch"/>
  </contact>

  <keyframe>
    <!-- 比原来多1个joint-->
    <key name="home" qpos="0 -1.57079 1.57079 1.57079 -1.57079 -0.7853 0.04 0.04" ctrl="0 -1.57079 1.57079 1.57079 -1.57079 -1.57079 0"/>
  </keyframe>
</mujoco>
